Workbook

Sheet Inputs
A1: Project Keystone - Model Inputs and Locked Deal Ledger v1.2
A2: Field | B2: Value | C2: Unit | D2: Status | E2: Source / Ledger ID | F2: Notes
A3: Enterprise value | B3: 108 | C3: $mm | D3: LOCKED | E3: KS-DL-1.2 | F3: Cash-free, debt-free
A4: Seller net debt and debt-like items | B4: 10.2 | C4: $mm | D4: LOCKED | E4: KS-DL-1.2 | F4: Closing estimate
A5: Seller equity value | B5: 97.8 | C5: $mm | D5: DERIVED | E5: EV less seller net debt
A6: Cash consideration | B6: 85.8 | C6: $mm | D6: DERIVED | E6: Seller equity less rollover
A7: Seller rollover | B7: 12 | C7: $mm | D7: LOCKED | E7: KS-DL-1.2 | F7: Founder $8.0m; management $4.0m
A8: Sponsor initial cash equity | B8: 62 | C8: $mm | D8: LOCKED | E8: KS-DL-1.2 | F8: Corrected capitalization
A9: First-lien opening debt | B9: 42.8 | C9: $mm | D9: LOCKED | E9: KS-DL-1.2
A10: Opening cash | B10: 3 | C10: $mm | D10: LOCKED | E10: KS-DL-1.2
A11: Opening firm EBITDA | B11: 11.4 | C11: $mm | D11: LOCKED | E11: KS-DL-1.2 | F11: Valuation and internal leverage
A12: Opening covenant EBITDA | B12: 12.2 | C12: $mm | D12: LOCKED | E12: KS-DL-1.2 | F12: Credit agreement only
A13: Largest ultimate-parent concentration | B13: 0.182 | C13: % | D13: LOCKED | E13: KS-DL-1.2 | F13: Riverton Industrial Group
A14: Normalized NWC target | B14: 8.4 | C14: $mm | D14: LOCKED | E14: KS-DL-1.2 | F14: Dollar-for-dollar true-up
A15: Tax rate | B15: 0.26 | C15: % | D15: MODEL ASSUMPTION | E15: KS-MA-001 | F15: Blended federal/state cash and book rate
A16: Cash interest deduction cap | B16: 0.3 | C16: % of EBITDA | D16: MODEL ASSUMPTION | E16: KS-MA-002 | F16: Simplified 163(j) treatment
A17: Depreciation as % revenue | B17: 0.015 | C17: % | D17: MODEL ASSUMPTION | E17: KS-MA-003 | F17: Consistent with historical run-rate
A18: Maintenance capex share | B18: 0.75 | C18: % of capex | D18: MODEL ASSUMPTION | E18: KS-MA-004 | F18: Growth capex is residual
A19: Eligible cash netting cap | B19: 5 | C19: $mm | D19: LOCKED | E19: KS-DL-1.2 | F19: Covenant only
A20: Revolver commitment | B20: 7.5 | C20: $mm | D20: LOCKED | E20: KS-DL-1.2
A21: DDTL commitment | B21: 10 | C21: $mm | D21: LOCKED | E21: KS-DL-1.2
A22: LC sublimit | B22: 2 | C22: $mm | D22: LOCKED | E22: KS-DL-1.2
A23: Term loan spread | B23: 0.055 | C23: % | D23: LOCKED | E23: KS-DL-1.2 | F23: Over adjusted Term SOFR
A24: Revolver spread | B24: 0.05 | C24: % | D24: LOCKED | E24: KS-DL-1.2
A25: DDTL spread | B25: 0.0575 | C25: % | D25: LOCKED | E25: KS-DL-1.2
A26: SOFR floor | B26: 0.01 | C26: % | D26: LOCKED | E26: KS-DL-1.2
A27: Annual term amortization | B27: 0.01 | C27: % original principal | D27: LOCKED | E27: KS-DL-1.2 | F27: Quarterly payments
A28: Annual DDTL amortization | B28: 0.01 | C28: % original principal | D28: LOCKED | E28: KS-DL-1.2 | F28: Quarterly after draw
A29: Unused revolver fee | B29: 0.005 | C29: % | D29: LOCKED | E29: KS-DL-1.2
A30: Unused DDTL fee | B30: 0.01 | C30: % | D30: LOCKED | E30: KS-DL-1.2 | F30: After first 90 days
A31: Financing fees and OID | B31: 1.4 | C31: $mm | D31: LOCKED | E31: KS-DL-1.2 | F31: Amortized over 24 quarters
A32: Buyer transaction expenses | B32: 4.4 | C32: $mm | D32: LOCKED | E32: KS-DL-1.2 | F32: Expensed at closing
A33: Opening equity after transaction expense | B33: 69.6 | C33: $mm | D33: DERIVED | E33: 74.0 less 4.4
A34: Exit date | B34: 47938 | C34: date | D34: LOCKED | E34: KS-DL-1.2 | F34: Exact LTM basis
A38: Annual Operating Assumptions
A39: Case / Driver | B39: Unit | C39: 2026 | D39: 2027 | E39: 2028 | F39: 2029 | G39: 2030 | H39: 2031
A40: Standalone Base - Platform growth | B40: % | C40: 0.07 | D40: 0.07 | E40: 0.07 | F40: 0.07 | G40: 0.07 | H40: 0.07
A41: Standalone Base - Gross margin | B41: % | C41: 0.362 | D41: 0.365 | E41: 0.368 | F41: 0.371 | G41: 0.374 | H41: 0.377
A42: Standalone Base - Firm EBITDA margin | B42: % | C42: 0.156 | D42: 0.161 | E42: 0.165 | F42: 0.169 | G42: 0.173 | H42: 0.177
A43: Standalone Base - DSO | B43: days | C43: 64 | D43: 63 | E43: 62 | F43: 61 | G43: 60 | H43: 60
...

Sheet Hist_3Stmt
A1: Historical Three-Statement Financials ($mm)
A3: Income Statement | B3: Unit | C3: FY2023A | D3: FY2024A | E3: FY2025A | G3: Historical data source map
A4: Revenue | B4: $mm | C4: 56.8 | D4: 65.4 | E4: 74 | G4: Revenue / GP / EBITDA | H4: KS-DL-1.2
A5: Growth | B5: % | D5: 0.151 | E5: 0.131 | G5: D&A / interest / tax | H5: KS-MA-HIST-001 | I5: Synthetic statement completion assumptions
A6: COGS | B6: $mm | C6: -37.4 | D6: -42.5 | E6: -47.4 | G6: Balance-sheet detail | H6: KS-MA-HIST-002 | I6: Constructed to tie to locked NWC, cash and debt
A7: Gross profit | B7: $mm | C7: 19.4 | D7: 22.9 | E7: 26.6 | G7: Cash-flow financing | H7: KS-MA-HIST-003 | I7: Owner activity reconciles equity and cash
A8: Gross margin | B8: % | C8: 0.342 | D8: 0.35 | E8: 0.359 | G8: All figures fictional | H8: Yes
A9: SG&A | B9: $mm | C9: -11.9 | D9: -14.1 | E9: -16.4
A10: Reported EBITDA | B10: $mm | C10: 7.5 | D10: 8.8 | E10: 10.2
A11: EBITDA margin | B11: % | C11: 0.132 | D11: 0.135 | E11: 0.138
A12: D&A | B12: $mm | C12: -1.1 | D12: -1.3 | E12: -1.5
A13: EBIT | B13: $mm | C13: 6.4 | D13: 7.5 | E13: 8.7
A14: Cash interest | B14: $mm | C14: -0.75 | D14: -0.85 | E14: -0.95
A15: Pre-tax income | B15: $mm | C15: 5.65 | D15: 6.65 | E15: 7.75
A16: Book tax expense | B16: $mm | C16: -1.47 | D16: -1.73 | E16: -2.02
A17: Net income | B17: $mm | C17: 4.18 | D17: 4.92 | E17: 5.73
A20: Balance Sheet
A21: Balance Sheet | B21: Unit | C21: FY2023A | D21: FY2024A | E21: FY2025A
A22: Cash | B22: $mm | C22: 2.5 | D22: 3.2 | E22: 4.2
A23: Accounts receivable | B23: $mm | C23: 9.8 | D23: 11.3 | E23: 13.2
A24: Unbilled WIP | B24: $mm | C24: 3.4 | D24: 4.2 | E24: 5.1
A25: Prepaids | B25: $mm | C25: 0.7 | D25: 0.8 | E25: 0.9
A26: PP&E, net | B26: $mm | C26: 4 | D26: 3.7 | E26: 3.4
A27: Goodwill | B27: $mm | C27: 18 | D27: 23 | E27: 28
A28: Other intangibles | B28: $mm | C28: 6 | D28: 8.5 | E28: 10
A29: Other assets | B29: $mm | C29: 1 | D29: 1.2 | E29: 1.3
A30: Total assets | B30: $mm | C30: 45.4 | D30: 55.9 | E30: 66.1
A31: Accounts payable | B31: $mm | C31: 2.9 | D31: 3.5 | E31: 4.1
A32: Accrued liabilities | B32: $mm | C32: 4.1 | D32: 4.8 | E32: 5.6
A33: Deferred revenue | B33: $mm | C33: 0.6 | D33: 0.8 | E33: 0.9
... A41: Balance check | B41: $mm | C41: 0 | D41: 0 | E41: 0
A44: Cash Flow Statement
A45: Cash Flow Statement | B45: Unit | C45: FY2023A | D45: FY2024A | E45: FY2025A
A46: Net income | B46: $mm | C46: 4.18 | D46: 4.92 | E46: 5.73
A47: D&A | B47: $mm | C47: 1.1 | D47: 1.3 | E47: 1.5
A48: Change in operating NWC | B48: $mm | C48: -0.5 | D48: -0.9 | E48: -1.4
A49: Cash from operations | B49: $mm | C49: 4.78 | D49: 5.32 | E49: 5.83
A50: Capital expenditure | B50: $mm | C50: -0.8 | D50: -1 | E50: -1.2
A51: Acquisitions, net | B51: $mm | C51: -5 | D51: -7 | E51: 0
A52: Cash from investing | B52: $mm | C52: -5.8 | D52: -8 | E52: -1.2
...

Sheet Hist_Monthly
A1: Monthly Management Accounts - FY2023A to FY2025A ($mm)
A3: Line Item | B3: Unit | C3: 44927 | D3: 44958 | E3: 44986 | F3: 45017 | G3: 45047 | H3: 45078 | I3: 45108 | J3: 45139 | K3: 45170 | L3: 45200 | M3: 45231 | N3: 45261 | O3: 45292 | P3: 45323 | Q3: 45352 | R3: 45383 | S3: 45413 | T3: 45444 | U3: 45474 | V3: 45505 | W3: 45536 | X3: 45566 | Y3: 45597 | Z3: 45627 | AA3: 45658 | AB3: 45689 | AC3: 45717 | AD3: 45748 | AE3: 45778 | AF3: 45809 | AG3: 45839 | AH3: 45870 | AI3: 45901 | AJ3: 45931 | AK3: 45962 | AL3: 45992
A4: Revenue | B4: $mm | C4: 4.26 | D4: 4.3736 | E4: 4.4304 | F4: 4.544 | G4: 4.6576 | H4: 4.7144 | I4: 4.7712 | J4: 4.828 | K4: 4.828 | L4: 4.9416 | M4: 5.1688 | N4: 5.2824 | O4: 4.905 | P4: 5.0358 | Q4: 5.1012 | R4: 5.232 | S4: 5.3628 | T4: 5.4282 | U4: 5.4936 | V4: 5.559 | W4: 5.559 | X4: 5.6898 | Y4: 5.9514 | Z4: 6.0822 | AA4: 5.55 | AB4: 5.698 | AC4: 5.772 | AD4: 5.92 | AE4: 6.068 | AF4: 6.142 | AG4: 6.216 | AH4: 6.29 | AI4: 6.29 | AJ4: 6.438 | AK4: 6.734 | AL4: 6.882
A5: Gross profit | B5: $mm | C5: 1.455 | D5: 1.4938 | E5: 1.5132 | F5: 1.552 | G5: 1.5908 | H5: 1.6102 | I5: 1.6296 | J5: 1.649 | K5: 1.649 | L5: 1.6878 | M5: 1.7654 | N5: 1.8042 | O5: 1.7175 | P5: 1.7633 | Q5: 1.7862 | R5: 1.832 | S5: 1.8778 | T5: 1.9007 | U5: 1.9236 | V5: 1.9465 | W5: 1.9465 | X5: 1.9923 | Y5: 2.0839 | Z5: 2.1297 | AA5: 1.995 | AB5: 2.0482 | AC5: 2.0748 | AD5: 2.128 | AE5: 2.1812 | AF5: 2.2078 | AG5: 2.2344 | AH5: 2.261 | AI5: 2.261 | AJ5: 2.3142 | AK5: 2.4206 | AL5: 2.4738
A6: Gross margin | B6: % | C6: 0.3415493 | D6: 0.3415493 | E6: 0.3415493 | F6: 0.3415493 | G6: 0.3415493 | H6: 0.3415493 | I6: 0.3415493 | J6: 0.3415493 | K6: 0.3415493 | L6: 0.3415493 | M6: 0.3415493 | N6: 0.3415493 | O6: 0.35015291 | P6: 0.35015291 | Q6: 0.35015291 | R6: 0.35015291 | S6: 0.35015291 | T6: 0.35015291 | U6: 0.35015291 | V6: 0.35015291 | W6: 0.35015291 | X6: 0.35015291 | Y6: 0.35015291 | Z6: 0.35015291 | AA6: 0.35945946 | AB6: 0.35945946 | AC6: 0.35945946 | AD6: 0.35945946 | AE6: 0.35945946 | AF6: 0.35945946 | AG6: 0.35945946 | AH6: 0.35945946 | AI6: 0.35945946 | AJ6: 0.35945946 | AK6: 0.35945946 | AL6: 0.35945946
A7: Reported EBITDA | B7: $mm | C7: 0.5625 | D7: 0.5775 | E7: 0.585 | F7: 0.6 | G7: 0.615 | H7: 0.6225 | I7: 0.63 | J7: 0.6375 | K7: 0.6375 | L7: 0.6525 | M7: 0.6825 | N7: 0.6975 | O7: 0.66 | P7: 0.6776 | Q7: 0.6864 | R7: 0.704 | S7: 0.7216 | T7: 0.7304 | U7: 0.7392 | V7: 0.748 | W7: 0.748 | X7: 0.7656 | Y7: 0.8008 | Z7: 0.8184 | AA7: 0.765 | AB7: 0.7854 | AC7: 0.7956 | AD7: 0.816 | AE7: 0.8364 | AF7: 0.8466 | AG7: 0.8568 | AH7: 0.867 | AI7: 0.867 | AJ7: 0.8874 | AK7: 0.9282 | AL7: 0.9486
A8: EBITDA margin | B8: % | C8: 0.13204225 | D8: 0.13204225 | E8: 0.13204225 | F8: 0.13204225 | G8: 0.13204225 | H8: 0.13204225 | I8: 0.13204225 | J8: 0.13204225 | K8: 0.13204225 | L8: 0.13204225 | M8: 0.13204225 | N8: 0.13204225 | O8: 0.13455657 | P8: 0.13455657 | Q8: 0.13455657 | R8: 0.13455657 | S8: 0.13455657 | T8: 0.13455657 | U8: 0.13455657 | V8: 0.13455657 | W8: 0.13455657 | X8: 0.13455657 | Y8: 0.13455657 | Z8: 0.13455657 | AA8: 0.13783784 | AB8: 0.13783784 | AC8: 0.13783784 | AD8: 0.13783784 | AE8: 0.13783784 | AF8: 0.13783784 | AG8: 0.13783784 | AH8: 0.13783784 | AI8: 0.13783784 | AJ8: 0.13783784 | AK8: 0.13783784 | AL8: 0.13783784
A9: Capex | B9: $mm | C9: 0.06 | D9: 0.0616 | E9: 0.0624 | F9: 0.064 | G9: 0.0656 | H9: 0.0664 | I9: 0.0672 | J9: 0.068 | K9: 0.068 | L9: 0.0696 | M9: 0.0728 | N9: 0.0744 | O9: 0.075 | P9: 0.077 | Q9: 0.078 | R9: 0.08 | S9: 0.082 | T9: 0.083 | U9: 0.084 | V9: 0.085 | W9: 0.085 | X9: 0.087 | Y9: 0.091 | Z9: 0.093 | AA9: 0.09 | AB9: 0.0924 | AC9: 0.0936 | AD9: 0.096 | AE9: 0.0984 | AF9: 0.0996 | AG9: 0.1008 | AH9: 0.102 | AI9: 0.102 | AJ9: 0.1044 | AK9: 0.1092 | AL9: 0.1116

Sheet Customer_Data
A1: Raw Customer Revenue Schedule - FY2025A
A3: Billing Account ID | B3: Billing Account | C3: Ultimate Parent | D3: Service Line | E3: End Market | F3: Region | G3: 2025 Revenue ($mm) | H3: % Revenue | I3: Recurring / Repeat / Project | J3: Contract Start | K3: Termination Notice (days) | L3: Minimum Volume | M3: Change of Control | N3: Relationship Tenure (yrs) | O3: Source
A4: RIV-DEC | B4: Riverton Advanced Materials - Decatur | C4: Riverton Industrial Group | D4: EHS Compliance | E4: Industrial manufacturing | F4: Midwest | G4: 5.624 | H4: 0.076 | I4: Repeat | J4: 42767 | K4: 60 | L4: No | M4: Notice | N4: 9 | O4: Customer ledger / KS-DL-1.2
A5: MET-N | B5: Metro Utility - North | C5: Metro Utility Holdings | D5: Field Inspection | E5: Infrastructure and utilities | F5: Midwest | G5: 3.2 | H5: 0.043243243 | I5: Recurring | J5: 43160 | K5: 90 | L5: No | M5: Consent | N5: 7 | O5: Customer ledger / KS-DL-1.2
A6: STA-01 | B6: State Infrastructure Department | C6: State Infrastructure Authority | D6: Permitting & Advisory | E6: Municipal and public sector | F6: Southeast | G6: 2.8 | H6: 0.037837838 | I6: Repeat | J6: 43556 | K6: 30 | L6: No | M6: Notice | N6: 11 | O6: Customer ledger / KS-DL-1.2
A7: MED-01 | B7: MedCore Hospital System | C7: MedCore Health | D7: Industrial Hygiene | E7: Healthcare and life sciences | F7: Midwest | G7: 2.3 | H7: 0.031081081 | I7: Recurring | J7: 43952 | K7: 60 | L7: No | M7: Notice | N7: 8 | O7: Customer ledger / KS-DL-1.2
A8: RIV-CORP | B8: Riverton Corporate EHS | C8: Riverton Industrial Group | D8: EHS Compliance | E8: Industrial manufacturing | F8: Midwest | G8: 1.912 | H8: 0.025837838 | I8: Recurring | J8: 44348 | K8: 60 | L8: No | M8: Notice | N8: 9 | O8: Customer ledger / KS-DL-1.2
A9: BIO-01 | B9: BioHealth Laboratories | C9: BioHealth Laboratories | D9: Industrial Hygiene | E9: Healthcare and life sciences | F9: Southeast | G9: 1.7 | H9: 0.022972973 | I9: Recurring | J9: 44743 | K9: 60 | L9: No | M9: Notice | N9: 6 | O9: Customer ledger / KS-DL-1.2
A10: APX-01 | B10: Apex Manufacturing - Main | C10: Apex Manufacturing | D10: EHS Compliance | E10: Industrial manufacturing | F10: Midwest | G10: 1.6 | H10: 0.021621622 | I10: Repeat | J10: 45139 | K10: 30 | L10: No | M10: None | N10: 5 | O10: Customer ledger / KS-DL-1.2
A11: RIV-GRN | B11: Riverton Components - Greenville | C11: Riverton Industrial Group | D11: Field Inspection | E11: Industrial manufacturing | F11: Southeast | G11: 1.5 | H11: 0.02027027 | I11: Repeat | J11: 42614 | K11: 60 | L11: No | M11: Notice | N11: 7 | O11: Customer ledger / KS-DL-1.2
A12: MET-S | B12: Metro Utility - South | C12: Metro Utility Holdings | D12: Field Inspection | E12: Infrastructure and utilities | F12: Southeast | G12: 1.4 | H12: 0.018918919 | I12: Recurring | J12: 43009 | K12: 90 | L12: No | M12: Consent | N12: 6 | O12: Customer ledger / KS-DL-1.2
A13: STA-02 | B13: State Infrastructure District 2 | C13: State Infrastructure Authority | D13: Permitting & Advisory | E13: Municipal and public sector | F13: Southeast | G13: 1.274 | H13: 0.017216216 | I13: Repeat | J13: 43405 | K13: 30 | L13: No | M13: Notice | N13: 10 | O13: Customer ledger / KS-DL-1.2
A14: RIV-MIL | B14: Riverton Metals - Milltown | C14: Riverton Industrial Group | D14: Industrial Hygiene | E14: Industrial manufacturing | F14: Midwest | G14: 1.3 | H14: 0.017567568 | I14: Recurring | J14: 43800 | K14: 60 | L14: No | M14: Notice | N14: 8 | O14: Customer ledger / KS-DL-1.2
A15: RIV-CHEM | B15: Riverton Chemicals - East | C15: Riverton Industrial Group | D15: EHS Compliance | E15: Industrial manufacturing | F15: Midwest | G15: 1.2 | H15: 0.016216216 | I15: Repeat | J15: 43831 | K15: 60 | L15: No | M15: Notice | N15: 6 | O15: Customer ledger / KS-DL-1.2
... A62: SM-035 | B62: Meridian Transit 2 Account 35 | C62: Meridian Transit 2 | D62: Field Inspection | E62: Infrastructure and utilities | F62: Midwest | G62: 0.84245998 | H62: 0.011384594 | I62: Project | J62: 43800 | K62: 60 | L62: No | M62: Notice | N62: 3 | O62: Customer ledger / KS-DL-1.2
A64: Concentration Summary
A65: Metric | B65: Billing-account view | C65: Ultimate-parent view | D65: Ledger target | E65: Check
A66: Largest customer | B66: 0.076 | C66: 0.182 | D66: 0.182
A67: Top five | B67: 0.214 | C67: 0.365 | D67: 0.365
A68: Top ten | B68: 0.315 | C68: 0.505 | D68: 0.505
A69: Total revenue | B69: 74 | C69: 74 | D69: 74

Sheet Project_Data
A1: Project-Level Revenue, Margin, Backlog and Contract Schedule - FY2025A
A3: Project ID | B3: Billing Account ID | C3: Ultimate Parent | D3: Service Line | E3: Project Type | F3: Start Date | G3: End / Renewal Date | H3: 2025 Revenue ($mm) | I3: Gross Margin % | J3: Unbilled WIP ($mm) | K3: WIP Age (days) | L3: Contracted Backlog ($mm) | M3: Expected Recurring Revenue ($mm) | N3: Termination Notice | O3: PO Required | P3: System | Q3: Branch | R3: Source
A4: RIV-DEC-P1 | B4: RIV-DEC | C4: Riverton Industrial Group | D4: EHS Compliance | E4: Repeat | F4: 45323 | G4: 46082 | H4: 1.6179894 | I4: 0.30724363 | J4: 0.10807215 | K4: 56 | L4: 0.74103742 | M4: 0.40449736 | N4: 30-60 days | O4: Yes | P4: Central PSA | Q4: Charlotte | R4: Project ledger / data room
A5: RIV-DEC-P2 | B5: RIV-DEC | C5: Riverton Industrial Group | D5: EHS Compliance | E5: Repeat | F5: 45352 | G5: 46143 | H5: 0.75369881 | I5: 0.35074357 | J5: 0.031560974 | K5: 63 | L5: 0.35412948 | M5: 0.1884247 | N5: 30-60 days | O5: No | P5: Legacy A | Q5: Indianapolis | R5: Project ledger / data room
A6: RIV-DEC-P3 | B6: RIV-DEC | C6: Riverton Industrial Group | D6: EHS Compliance | E6: Repeat | F6: 45383 | G6: 46204 | H6: 3.2523117 | I6: 0.3090713 | J6: 0.19912591 | K6: 102 | L6: 1.7035673 | M6: 0.81307794 | N6: 30-60 days | O6: Yes | P6: Legacy B | Q6: Chicago | R6: Project ledger / data room
A7: MET-N-P1 | B7: MET-N | C7: Metro Utility Holdings | D7: Field Inspection | E7: Recurring | F7: 45323 | G7: 46082 | H7: 0.39722653 | I7: 0.35771029 | J7: 0.023767661 | K7: 117 | L7: 0.17739449 | M7: 0.19861326 | N7: 30-60 days | O7: Yes | P7: Legacy B | Q7: Indianapolis | R7: Project ledger / data room
A8: MET-N-P2 | B8: MET-N | C8: Metro Utility Holdings | D8: Field Inspection | E8: Recurring | F8: 45352 | G8: 46143 | H8: 1.1164409 | I8: 0.38584685 | J8: 0.060824221 | K8: 34 | L8: 0.57808445 | M8: 0.55822047 | N8: 30-60 days | O8: No | P8: Central PSA | Q8: Chicago | R8: Project ledger / data room
A9: MET-N-P3 | B9: MET-N | C9: Metro Utility Holdings | D9: Field Inspection | E9: Recurring | F9: 45383 | G9: 46204 | H9: 1.6863325 | I9: 0.33084818 | J9: 0.13626632 | K9: 38 | L9: 1.6553043 | M9: 0.84316627 | N9: 30-60 days | O9: Yes | P9: Legacy A | Q9: Louisville | R9: Project ledger / data room
A10: STA-01-P1 | B10: STA-01 | C10: State Infrastructure Authority | D10: Permitting & Advisory | E10: Repeat | F10: 45323 | G10: 46082 | H10: 1.1474625 | I10: 0.3062789 | J10: 0.049318006 | K10: 40 | L10: 1.2397185 | M10: 0.28686563 | N10: 30-60 days | O10: Yes | P10: Legacy A | Q10: Nashville | R10: Project ledger / data room
A11: STA-01-P2 | B11: STA-01 | C11: State Infrastructure Authority | D11: Permitting & Advisory | E11: Repeat | F11: 45352 | G11: 46143 | H11: 0.66881079 | I11: 0.34275923 | J11: 0.037257682 | K11: 78 | L11: 0.57061891 | M11: 0.1672027 | N11: 30-60 days | O11: No | P11: Legacy B | Q11: Raleigh | R11: Project ledger / data room
A12: STA-01-P3 | B12: STA-01 | C12: State Infrastructure Authority | D12: Permitting & Advisory | E12: Repeat | F12: 45383 | G12: 46204 | H12: 0.9837267 | I12: 0.3299767 | J12: 0.078421684 | K12: 89 | L12: 0.63361494 | M12: 0.24593168 | N12: 30-60 days | O12: Yes | P12: Central PSA | Q12: Charlotte | R12: Project ledger / data room
A13: MED-01-P1 | B13: MED-01 | C13: MedCore Health | D13: Industrial Hygiene | E13: Recurring | F13: 45323 | G13: 46082 | H13: 0.66903121 | I13: 0.37294453 | J13: 0.036393216 | K13: 118 | L13: 0.34660217 | M13: 0.3345156 | N13: 30-60 days | O13: Yes | P13: Legacy B | Q13: Raleigh | R13: Project ledger / data room
A14: MED-01-P2 | B14: MED-01 | C14: MedCore Health | D14: Industrial Hygiene | E14: Recurring | F14: 45352 | G14: 46143 | H14: 0.61169629 | I14: 0.34181228 | J14: 0.047624866 | K14: 35 | L14: 0.54377543 | M14: 0.30584814 | N14: 30-60 days | O14: No | P14: Central PSA | Q14: Charlotte | R14: Project ledger / data room
A15: MED-01-P3 | B15: MED-01 | C15: MedCore Health | D15: Industrial Hygiene | E15: Recurring | F15: 45383 | G15: 46204 | H15: 1.0192725 | I15: 0.30392073 | J15: 0.074825603 | K15: 96 | L15: 0.99177859 | M15: 0.50963625 | N15: 30-60 days | O15: Yes | P15: Legacy A | Q15: Indianapolis | R15: Project ledger / data room
... A118: SM-035-P1 | B118: SM-035 | C118: Meridian Transit 2 | D118: Field Inspection | E118: Project | F118: 45323 | G118: 46082 | H118: 0.84245998 | I118: 0.3189849 | J118: 0.049424991 | K118: 115 | L118: 1.0819432 | M118: 0.042122999 | N118: 30-60 days | O118: Yes | P118: Central PSA | Q118: Indianapolis | R118: Project ledger / data room

Sheet Employees
A1: Employee and Utilization Schedule - December 31, 2025
A3: Employee ID | B3: Office | C3: Region | D3: Function | E3: Service Line | F3: Billable? | G3: Annual Base Salary ($000) | H3: Bonus Target % | I3: Recorded Utilization % | J3: Standardized Utilization % | K3: Hire Date | L3: Acquisition Origin | M3: Status | N3: Manager Level | O3: Retention Critical? | P3: Source
A4: E0001 | B4: Chicago | C4: Midwest | D4: Technical | E4: Industrial Hygiene | F4: Yes | G4: 77 | H4: 0.05 | I4: 0.62 | J4: 0.58 | K4: 42401 | L4: Northstar | M4: Active | N4: Staff | O4: No | P4: HRIS / KS-DL-1.2
A5: E0002 | B5: Detroit | C5: Midwest | D5: Technical | E5: Field Inspection | F5: Yes | G5: 94 | H5: 0.05 | I5: 0.69 | J5: 0.65 | K5: 42795 | L5: Delta | M5: Active | N5: Staff | O5: No | P5: HRIS / KS-DL-1.2
A6: E0003 | B6: Louisville | C6: Southeast | D6: Technical | E6: Permitting & Advisory | F6: Yes | G6: 111 | H6: 0.05 | I6: 0.76 | J6: 0.72 | K6: 43191 | L6: Meridian | M6: Active | N6: Staff | O6: No | P6: HRIS / KS-DL-1.2
A7: E0004 | B7: Nashville | C7: Midwest | D7: Project Management | E7: EHS Compliance | F7: Yes | G7: 128 | H7: 0.05 | I7: 0.83 | J7: 0.79 | K7: 43586 | L7: Summit | M7: Active | N7: Staff | O7: No | P7: HRIS / KS-DL-1.2
A8: E0005 | B8: Raleigh | C8: Midwest | D8: Corporate | E8: Industrial Hygiene | F8: No | G8: 135 | H8: 0.15 | I8: 0 | J8: 0 | K8: 43983 | L8: Legacy Alderstone | M8: Active | N8: Staff | O8: No | P8: HRIS / KS-DL-1.2
A9: E0006 | B9: Charlotte | C9: Southeast | D9: Sales | E9: Field Inspection | F9: No | G9: 148 | H9: 0.15 | I9: 0 | J9: 0 | K9: 44378 | L9: Northstar | M9: Active | N9: Staff | O9: No | P9: HRIS / KS-DL-1.2
A10: E0007 | B10: Cincinnati | C10: Midwest | D10: Finance | E10: Permitting & Advisory | F10: No | G10: 161 | H10: 0.15 | I10: 0 | J10: 0 | K10: 44774 | L10: Delta | M10: Active | N10: Staff | O10: No | P10: HRIS / KS-DL-1.2
A11: E0008 | B11: Columbus | C11: Midwest | D11: HR | E11: EHS Compliance | F11: No | G11: 174 | H11: 0.15 | I11: 0 | J11: 0 | K11: 45170 | L11: Meridian | M11: Active | N11: Staff | O11: No | P11: HRIS / KS-DL-1.2
A12: E0009 | B12: Knoxville | C12: Southeast | D12: IT | E12: Industrial Hygiene | F12: No | G12: 77 | H12: 0.15 | I12: 0 | J12: 0 | K12: 45566 | L12: Summit | M12: Active | N12: Staff | O12: No | P12: HRIS / KS-DL-1.2
A13: E0010 | B13: Greenville | C13: Midwest | D13: Technical | E13: Field Inspection | F13: Yes | G13: 140 | H13: 0.05 | I13: 0.65 | J13: 0.61 | K13: 45962 | L13: Legacy Alderstone | M13: Active | N13: Staff | O13: No | P13: HRIS / KS-DL-1.2
A14: E0011 | B14: Milwaukee | C14: Midwest | D14: Technical | E14: Permitting & Advisory | F14: Yes | G14: 67 | H14: 0.05 | I14: 0.72 | J14: 0.68 | K14: 42339 | L14: Northstar | M14: Active | N14: Staff | O14: No | P14: HRIS / KS-DL-1.2
A15: E0012 | B15: St. Louis | C15: Southeast | D15: Technical | E15: EHS Compliance | F15: Yes | G15: 84 | H15: 0.05 | I15: 0.79 | J15: 0.75 | K15: 42370 | L15: Delta | M15: Active | N15: Manager | O15: No | P15: HRIS / KS-DL-1.2
... A471: E0468 | B471: Charlotte | C471: Southeast | D471: HR | E471: EHS Compliance | F471: No | G471: 104 | H471: 0.15 | I471: 0 | J471: 0 | K471: 44197 | L471: Meridian | M471: Active | N471: Manager | O471: No | P471: HRIS / KS-DL-1.2

Sheet AR_WIP
A1: Accounts Receivable and Unbilled WIP Detail - December 31, 2025
A3: Accounts Receivable Detail
A4: Invoice ID | B4: Billing Account ID | C4: Ultimate Parent | D4: Invoice Date | E4: Due Date | F4: Amount ($mm) | G4: Age (days) | H4: Current | I4: 31-60 | J4: 61-90 | K4: 91-120 | L4: 120+ | M4: Disputed?
A5: INV-0001 | B5: MED-01 | C5: MedCore Health | D5: 46001 | E5: 46031 | F5: 0.089416841 | G5: 21 | H5: 0.089416841 | I5: 0 | J5: 0 | K5: 0 | L5: 0 | M5: No
A6: INV-0002 | B6: APX-01 | C6: Apex Manufacturing | D6: 45972 | E6: 46002 | F6: 0.20202858 | G6: 50 | H6: 0 | I6: 0.20202858 | J6: 0 | K6: 0 | L6: 0 | M6: No
A7: INV-0003 | B7: STA-02 | C7: State Infrastructure Authority | D7: 45896 | E7: 45926 | F7: 0.12536859 | G7: 126 | H7: 0 | I7: 0 | J7: 0 | K7: 0 | L7: 0.12536859 | M7: No
A8: INV-0004 | B8: RIV-LOG | C8: Riverton Industrial Group | D8: 45977 | E8: 46007 | F8: 0.093327516 | G8: 45 | H8: 0 | I8: 0.093327516 | J8: 0 | K8: 0 | L8: 0 | M8: No
A9: INV-0005 | B9: APX-02 | C9: Apex Manufacturing | D9: 46004 | E9: 46034 | F9: 0.16170985 | G9: 18 | H9: 0.16170985 | I9: 0 | J9: 0 | K9: 0 | L9: 0 | M9: No
A10: INV-0006 | B10: CTY-01 | C10: CityWorks Municipal Group | D10: 45873 | E10: 45903 | F10: 0.16276976 | G10: 149 | H10: 0 | I10: 0 | J10: 0 | K10: 0 | L10: 0.16276976 | M10: No
A11: INV-0007 | B11: CLN-02 | C11: Clinica Health | D11: 45941 | E11: 45971 | F11: 0.1594249 | G11: 81 | H11: 0 | I11: 0 | J11: 0.1594249 | K11: 0 | L11: 0 | M11: No
A12: INV-0008 | B12: SM-001 | C12: Northfield Foods | D12: 46020 | E12: 46050 | F12: 0.15439631 | G12: 2 | H12: 0.15439631 | I12: 0 | J12: 0 | K12: 0 | L12: 0 | M12: No
A13: INV-0009 | B13: SM-004 | C13: Granite Bio | D13: 45937 | E13: 45967 | F13: 0.10894482 | G13: 85 | H13: 0 | I13: 0 | J13: 0.10894482 | K13: 0 | L13: 0 | M13: No
A14: INV-0010 | B14: SM-007 | C14: Keystone Health | D14: 46001 | E14: 46031 | F14: 0.1064285 | G14: 21 | H14: 0.1064285 | I14: 0 | J14: 0 | K14: 0 | L14: 0 | M14: No
A15: INV-0011 | B15: SM-010 | C15: Pioneer Components | D15: 45998 | E15: 46028 | F15: 0.20916982 | G15: 24 | H15: 0.20916982 | I15: 0 | J15: 0 | K15: 0 | L15: 0 | M15: No
A16: INV-0012 | B16: SM-013 | C16: Silverline Medical | D16: 45912 | E16: 45942 | F16: 0.12299482 | G16: 110 | H16: 0 | I16: 0 | J16: 0 | K16: 0.12299482 | L16: 0 | M16: No
... A84: INV-0080 | B84: RIV-CORP | C84: Riverton Industrial Group | D84: 45891 | E84: 45921 | F84: 0.21151392 | G84: 131 | H84: 0 | I84: 0 | J84: 0 | K84: 0 | L84: 0.21151392 | M84: No
A86: Unbilled WIP Detail
A87: WIP ID | B87: Project ID | C87: Billing Account ID | D87: Ultimate Parent | E87: Service Line | F87: Amount ($mm) | G87: Age (days) | H87: Customer Approval Required? | I87: PO / Change Order Status | J87: Expected Bill Date | K87: Collectibility | L87: System | M87: Source
A88: WIP-0001 | B88: MET-N-P3 | C88: MET-N | D88: Metro Utility Holdings | E88: Field Inspection | F88: 0.11257358 | G88: 39 | H88: No | I88: Approved | J88: 46038 | K88: High | L88: Legacy A | M88: WIP ledger / data room
A89: WIP-0002 | B89: MED-01-P2 | C89: MED-01 | D89: MedCore Health | E89: Industrial Hygiene | F89: 0.12640718 | G89: 56 | H89: No | I89: Approved | J89: 46039 | K89: High | L89: Central PSA | M89: WIP ledger / data room
A90: WIP-0003 | B90: BIO-01-P2 | C90: BIO-01 | D90: BioHealth Laboratories | E90: Industrial Hygiene | F90: 0.092467299 | G90: 102 | H90: No | I90: Approved | J90: 46040 | K90: Review | L90: Central PSA | M90: WIP ledger / data room
A91: WIP-0004 | B91: MET-S-P1 | C91: MET-S | D91: Metro Utility Holdings | E91: Field Inspection | F91: 0.091315484 | G91: 64 | H91: Yes | I91: Approved | J91: 46041 | K91: High | L91: Central PSA | M91: WIP ledger / data room
A92: WIP-0005 | B92: RIV-MIL-P2 | C92: RIV-MIL | D92: Riverton Industrial Group | E92: Industrial Hygiene | F92: 0.07617644 | G92: 42 | H92: No | I92: Pending | J92: 46042 | K92: High | L92: Legacy B | M92: WIP ledger / data room
A93: WIP-0006 | B93: RIV-WST-P1 | C93: RIV-WST | D93: Riverton Industrial Group | E93: Permitting & Advisory | F93: 0.15360392 | G93: 94 | H93: No | I93: Approved | J93: 46043 | K93: Review | L93: Central PSA | M93: WIP ledger / data room
A94: WIP-0007 | B94: APX-02-P2 | C94: APX-02 | D94: Apex Manufacturing | E94: Field Inspection | F94: 0.062806912 | G94: 6 | H94: No | I94: Approved | J94: 46044 | K94: High | L94: Central PSA | M94: WIP ledger / data room
A95: WIP-0008 | B95: CTY-01-P1 | C95: CTY-01 | D95: CityWorks Municipal Group | E95: Permitting & Advisory | F95: 0.044696954 | G95: 29 | H95: Yes | I95: Approved | J95: 46045 | K95: High | L95: Central PSA | M95: WIP ledger / data room
A96: WIP-0009 | B96: CLN-01-P2 | C96: CLN-01 | D96: Clinica Health | E96: Industrial Hygiene | F96: 0.059176534 | G96: 96 | H96: No | I96: Approved | J96: 46046 | K96: Review | L96: Central PSA | M96: WIP ledger / data room
A97: WIP-0010 | B97: SM-001-P1 | C97: SM-001 | D97: Northfield Foods | E97: EHS Compliance | F97: 0.059094217 | G97: 105 | H97: No | I97: Pending | J97: 46047 | K97: Review | L97: Legacy A | M97: WIP ledger / data room
A98: WIP-0011 | B98: SM-003-P2 | C98: SM-003 | D98: Cedar Municipal | E98: Field Inspection | F98: 0.067684239 | G98: 14 | H98: No | I98: Approved | J98: 46048 | K98: High | L98: Central PSA | M98: WIP ledger / data room
A99: WIP-0012 | B99: SM-006-P1 | C99: SM-006 | D99: Summit Water | E99: Industrial Hygiene | F99: 0.060053413 | G99: 9 | H99: Yes | I99: Approved | J99: 46049 | K99: High | L99: Legacy A | M99: WIP ledger / data room
... A147: WIP-0060 | B147: SM-011-P1 | C147: SM-011 | D147: Evergreen Chemicals | E147: Field Inspection | F147: 0.042145927 | G147: 118 | H147: Yes | I147: Pending | J147: 46097 | K147: Review | L147: Legacy B | M147: WIP ledger / data room

Sheet QoE_Bridge
A1: EBITDA Basis Schedule ($mm)
A3: Adjustment | B3: Reported | C3: Seller View | D3: QoE View | E3: Firm View | F3: Covenant View | G3: Source / Treatment
A4: Reported EBITDA | B4: 10.2 | C4: 10.2 | D4: 10.2 | E4: 10.2 | F4: 10.2 | G4: Historical accounts
A5: Founder / executive compensation | B5: 0 | C5: 0.4 | D5: 0.35 | E5: 0.35 | F5: 0.35 | G5: QoE accepted at market replacement cost
A6: Transaction-readiness and professional fees | B6: 0 | C6: 0.3 | D6: 0.25 | E6: 0.25 | F6: 0.25 | G6: Recurring audit/compliance retained
A7: Integration and systems costs | B7: 0 | C7: 0.5 | D7: 0.3 | E7: 0.2 | F7: 0.3 | G7: Firm retains $0.10m recurring cost
A8: Legal and settlement expense | B8: 0 | C8: 0.2 | D8: 0.2 | E8: 0.2 | F8: 0.2 | G8: Supported non-recurring item
A9: Duplicate occupancy / facility move | B9: 0 | C9: 0.2 | D9: 0.15 | E9: 0.15 | F9: 0.15 | G9: Implemented closure
A10: Implemented headcount savings | B10: 0 | C10: 0.4 | D10: 0.25 | E10: 0.25 | F10: 0.5 | G10: Additional covenant-certified savings
A11: Pricing and utilization initiatives | B11: 0 | C11: 0.5 | D11: 0 | E11: 0 | F11: 0 | G11: Forecast only; no historical add-back
A12: Revenue cut-off | B12: 0 | C12: 0 | D12: -0.1 | E12: -0.1 | F12: -0.1 | G12: QoE correction
A13: Bonus accrual normalization | B13: 0 | C13: 0 | D13: 0.2 | E13: 0.2 | F13: 0.2 | G13: Approved plan support
A14: Related-party rent normalization | B14: 0 | C14: 0 | D14: 0.1 | E14: 0.1 | F14: 0 | G14: Not recognized in covenant definition
A15: Revenue / WIP quality reserve | B15: 0 | C15: 0 | D15: 0 | E15: -0.2 | F15: 0 | G15: Firm conservatism
... A19: Adjusted EBITDA | B19: 10.2 | C19: 12.7 | D19: 11.9 | E19: 11.4 | F19: 12.2 | G19: Model amounts

Sheet S&U_Opening
A1: Sources & Uses, Purchase Price Bridge and Opening Balance Sheet ($mm)
A3: Purchase Price Bridge | E3: Gross Sources and Uses
A4: Enterprise value | B4: 108 | E4: Sources | F4: Amount | G4: Uses | H4: Amount
A5: Less: seller net debt and debt-like items | B5: -10.2 | E5: First-lien term loan | F5: 42.8 | G5: Seller equity purchase price | H5: 97.8
A6: Seller equity value | B6: 97.8 | E6: Sponsor cash equity | F6: 62 | G6: Debt and debt-like settlement | H6: 14.4
A7: Less: seller rollover | B7: -12 | E7: Seller rollover equity | F7: 12 | G7: Buyer transaction expenses | H7: 4.4
A8: Cash consideration | B8: 85.8 | E8: Acquired cash | F8: 4.2 | G8: Financing fees and OID | H8: 1.4
E9: Total sources | F9: 121 | G9: Opening cash | H9: 3
G10: Total uses | H10: 121
E11: S&U check | F11: 0
A13: Opening Pro Forma Balance Sheet - March 31, 2026
A14: Assets | B14: Amount | D14: Liabilities and Equity | E14: Amount | G14: Source
A15: Cash | B15: 3 | D15: Accounts payable | E15: 4.1 | G15: KS-DL-1.2 / PPA
A16: Accounts receivable | B16: 13.2 | D16: Accrued liabilities | E16: 5.6 | G16: KS-DL-1.2 / PPA
A17: Unbilled WIP | B17: 4.9 | D17: Deferred revenue | E17: 0.9 | G17: KS-DL-1.2 / PPA
A18: Prepaids | B18: 0.9 | D18: Term loan | E18: 42.8 | G18: KS-DL-1.2 / PPA
A19: PP&E, net | B19: 3.4 | D19: Deferred tax liability | E19: 8.5 | G19: KS-DL-1.2 / PPA
A20: Goodwill | B20: 71 | D20: Other liabilities | E20: 1.6 | G20: KS-DL-1.2 / PPA
A21: Customer relationships | B21: 28 | D21: Equity | E21: 69.6 | G21: KS-DL-1.2 / PPA
A22: Trade name | B22: 5 | G22: KS-DL-1.2 / PPA
A23: Non-compete | B23: 1 | G23: KS-DL-1.2 / PPA
A24: Deferred financing fees | B24: 1.4 | G24: KS-DL-1.2 / PPA
A25: Other assets | B25: 1.3 | G25: KS-DL-1.2 / PPA
A26: Total assets | B26: 133.1 | D26: Total liabilities & equity | E26: 133.1
A27: Balance sheet check | B27: 0

Sheet Purchase_Accounting
A1: Purchase Accounting and Intangible Amortization ($mm)
A3: Allocation Item | B3: Fair Value | C3: Useful Life | D3: Annual Amortization | E3: Tax Basis | F3: Source / Assumption
A4: Normalized net working capital | B4: 8.4 | C4: N/A | D4: 0 | E4: Carryover | F4: KS-DL-1.2
A5: PP&E | B5: 3.4 | C5: 5 years | D5: 0.68 | E5: Carryover | F5: KS-DL-1.2 / model
A6: Other net operating assets | B6: -0.3 | C6: N/A | D6: 0 | E6: Carryover | F6: Model completion assumption
A7: Customer relationships | B7: 28 | C7: 10 years | D7: 2.8 | E7: No step-up | F7: KS-MA-PPA-001
A8: Trade name | B8: 5 | C8: Indefinite | D8: 0 | E8: No step-up | F8: KS-MA-PPA-002
A9: Non-compete | B9: 1 | C9: 5 years | D9: 0.2 | E9: No step-up | F9: KS-MA-PPA-003
A10: Deferred tax liability | B10: -8.5 | C10: N/A | D10: 0 | E10: N/A | F10: 26% of non-tax-deductible intangibles
A11: Goodwill | B11: 71 | C11: Indefinite | D11: 0 | E11: No step-up | F11: Residual
A12: Enterprise value | B12: 108 | D12: 3 | F12: Check

Sheet Seller_Model
A1: Seller Operating Model - Updated January 2026 Financial Supplement ($mm)
A3: Line Item | B3: FY2025A | C3: FY2026E | D3: FY2027E | E3: FY2028E | F3: FY2029E | G3: FY2030E | H3: Source
A4: Revenue | B4: 74 | C4: 82.1 | D4: 90.7 | E4: 100.1 | F4: 110 | G4: 120.4 | H4: CIM supplement
A5: Growth | B5: 0.131 | C5: 0.109 | D5: 0.105 | E5: 0.104 | F5: 0.099 | G5: 0.095 | H5: Management forecast
A6: Management-adjusted EBITDA | B6: 12.7 | C6: 15 | D6: 16.9 | E6: 18.9 | F6: 21.1 | G6: 23.5 | H6: Seller-defined EBITDA
A7: EBITDA margin | B7: 0.172 | C7: 0.183 | D7: 0.186 | E7: 0.189 | F7: 0.192 | G7: 0.195 | H7: Management forecast
A8: Capital expenditure | B8: 1.2 | C8: 1.3 | D8: 1.5 | E8: 1.6 | F8: 1.8 | G8: 1.9 | H8: Management forecast
A9: Capex / revenue | B9: 0.016 | C9: 0.016 | D9: 0.016 | E9: 0.016 | F9: 0.016 | G9: 0.016 | H9: Management forecast

Sheet Scenario_Drivers
A1: Quarterly Scenario Drivers and Transaction Events
A3: Driver | B3: Unit | C3: 46203 | D3: 46295 | E3: 46387 | F3: 46477 | G3: 46568 | H3: 46660 | I3: 46752 | J3: 46843 | K3: 46934 | L3: 47026 | M3: 47118 | N3: 47208 | O3: 47299 | P3: 47391 | Q3: 47483 | R3: 47573 | S3: 47664 | T3: 47756 | U3: 47848 | V3: 47938
A4: Standalone Base
A5: Revenue | B5: $mm | C5: 19.795 | D5: 20.5868 | E5: 20.5868 | F5: 19.486198 | G5: 21.18065 | H5: 22.027876 | I5: 22.027876 | J5: 20.850232 | K5: 22.663296 | L5: 23.569827 | M5: 23.569827 | N5: 22.309748 | O5: 24.249726 | P5: 25.219715 | Q5: 25.219715 | R5: 23.87143 | S5: 25.947207 | T5: 26.985095 | U5: 26.985095 | V5: 25.542431
A6: Gross margin | B6: % | C6: 0.362 | D6: 0.362 | E6: 0.362 | F6: 0.365 | G6: 0.365 | H6: 0.365 | I6: 0.365 | J6: 0.368 | K6: 0.368 | L6: 0.368 | M6: 0.368 | N6: 0.371 | O6: 0.371 | P6: 0.371 | Q6: 0.371 | R6: 0.374 | S6: 0.374 | T6: 0.374 | U6: 0.374 | V6: 0.377
A7: Firm EBITDA | B7: $mm | C7: 3.08802 | D7: 3.2115408 | E7: 3.2115408 | F7: 3.1372779 | G7: 3.4100847 | H7: 3.546488 | I7: 3.546488 | J7: 3.4402883 | K7: 3.7394438 | L7: 3.8890215 | M7: 3.8890215 | N7: 3.7703474 | O7: 4.0982037 | P7: 4.2621319 | Q7: 4.2621319 | R7: 4.1297575 | S7: 4.4888668 | T7: 4.6684215 | U7: 4.6684215 | V7: 4.5210102
A8: One-time charges | B8: $mm | C8: 0 | D8: 0 | E8: 0 | F8: 0 | G8: 0 | H8: 0 | I8: 0 | J8: 0 | K8: 0 | L8: 0 | M8: 0 | N8: 0 | O8: 0 | P8: 0 | Q8: 0 | R8: 0 | S8: 0 | T8: 0 | U8: 0 | V8: 0
A9: Covenant add-backs | B9: $mm | C9: 0 | D9: 0 | E9: 0 | F9: 0 | G9: 0 | H9: 0 | I9: 0 | J9: 0 | K9: 0 | L9: 0 | M9: 0 | N9: 0 | O9: 0 | P9: 0 | Q9: 0 | R9: 0 | S9: 0 | T9: 0 | U9: 0 | V9: 0
A10: DSO | B10: days | C10: 64 | D10: 64 | E10: 64 | F10: 63 | G10: 63 | H10: 63 | I10: 63 | J10: 62 | K10: 62 | L10: 62 | M10: 62 | N10: 61 | O10: 61 | P10: 61 | Q10: 61 | R10: 60 | S10: 60 | T10: 60 | U10: 60 | V10: 60
A11: WIP / annualized revenue | B11: % | C11: 0.067 | D11: 0.067 | E11: 0.067 | F11: 0.065 | G11: 0.065 | H11: 0.065 | I11: 0.065 | J11: 0.063 | K11: 0.063 | L11: 0.063 | M11: 0.063 | N11: 0.061 | O11: 0.061 | P11: 0.061 | Q11: 0.061 | R11: 0.06 | S11: 0.06 | T11: 0.06 | U11: 0.06 | V11: 0.06
A12: Prepaids / annualized revenue | B12: % | C12: 0.012 | D12: 0.012 | E12: 0.012 | F12: 0.012 | G12: 0.012 | H12: 0.012 | I12: 0.012 | J12: 0.012 | K12: 0.012 | L12: 0.012 | M12: 0.012 | N12: 0.012 | O12: 0.012 | P12: 0.012 | Q12: 0.012 | R12: 0.012 | S12: 0.012 | T12: 0.012 | U12: 0.012 | V12: 0.012
A13: AP / annualized revenue | B13: % | C13: 0.055 | D13: 0.055 | E13: 0.055 | F13: 0.055 | G13: 0.055 | H13: 0.055 | I13: 0.055 | J13: 0.055 | K13: 0.055 | L13: 0.055 | M13: 0.055 | N13: 0.055 | O13: 0.055 | P13: 0.055 | Q13: 0.055 | R13: 0.055 | S13: 0.055 | T13: 0.055 | U13: 0.055 | V13: 0.055
A14: Accruals / annualized revenue | B14: % | C14: 0.075 | D14: 0.075 | E14: 0.075 | F14: 0.075 | G14: 0.075 | H14: 0.075 | I14: 0.075 | J14: 0.075 | K14: 0.075 | L14: 0.075 | M14: 0.075 | N14: 0.075 | O14: 0.075 | P14: 0.075 | Q14: 0.075 | R14: 0.075 | S14: 0.075 | T14: 0.075 | U14: 0.075 | V14: 0.075
A15: Deferred revenue / annualized revenue | B15: % | C15: 0.012 | D15: 0.012 | E15: 0.012 | F15: 0.012 | G15: 0.012 | H15: 0.012 | I15: 0.012 | J15: 0.012 | K15: 0.012 | L15: 0.012 | M15: 0.012 | N15: 0.012 | O15: 0.012 | P15: 0.012 | Q15: 0.012 | R15: 0.012 | S15: 0.012 | T15: 0.012 | U15: 0.012 | V15: 0.012
A16: Capex / revenue | B16: % | C16: 0.016 | D16: 0.016 | E16: 0.016 | F16: 0.016 | G16: 0.016 | H16: 0.016 | I16: 0.016 | J16: 0.016 | K16: 0.016 | L16: 0.016 | M16: 0.016 | N16: 0.016 | O16: 0.016 | P16: 0.016 | Q16: 0.016 | R16: 0.016 | S16: 0.016 | T16: 0.016 | U16: 0.016 | V16: 0.016
... A36: Seasonality | B36: % | C36: 0.25 | D36: 0.26 | E36: 0.26 | F36: 0.23 | G36: 0.25 | H36: 0.26 | I36: 0.26 | J36: 0.23 | K36: 0.25 | L36: 0.26 | M36: 0.26 | N36: 0.23 | O36: 0.25 | P36: 0.26 | Q36: 0.26 | R36: 0.23 | S36: 0.25 | T36: 0.26 | U36: 0.26 | V36: 0.23
A38: Standalone Downside
A39: Revenue | B39: $mm | C39: 19.24 | D39: 20.0096 | E39: 20.0096 | F39: 18.054816 | G39: 19.6248 | H39: 20.409792 | I39: 20.409792 | J39: 18.777009 | K39: 20.409792 | L39: 21.226184 | M39: 21.226184 | N39: 19.715859 | O39: 21.430282 | P39: 22.287493 | Q39: 22.287493 | R39: 20.701652 | S39: 22.501796 | T39: 23.401868 | U39: 23.401868 | V39: 21.736735
A40: Gross margin | B40: % | C40: 0.355 | D40: 0.355 | E40: 0.355 | F40: 0.345 | G40: 0.345 | H40: 0.345 | I40: 0.345 | J40: 0.35 | K40: 0.35 | L40: 0.35 | M40: 0.35 | N40: 0.355 | O40: 0.355 | P40: 0.355 | Q40: 0.355 | R40: 0.36 | S40: 0.36 | T40: 0.36 | U40: 0.36 | V40: 0.362
A41: Firm EBITDA | B41: $mm | C41: 2.7898 | D41: 2.901392 | E41: 2.901392 | F41: 2.4374002 | G41: 2.649348 | H41: 2.7553219 | I41: 2.7553219 | J41: 2.7226663 | K41: 2.9594198 | L41: 3.0777966 | M41: 3.0777966 | N41: 3.0165264 | O41: 3.2788331 | P41: 3.4099864 | Q41: 3.4099864 | R41: 3.270861 | S41: 3.5552837 | T41: 3.6974951 | U41: 3.6974951 | V41: 3.521351
A42: One-time charges | B42: $mm | C42: 0 | D42: 0 | E42: 0 | F42: 0 | G42: 0 | H42: 0 | I42: 0 | J42: 0 | K42: 0 | L42: 0 | M42: 0 | N42: 0 | O42: 0 | P42: 0 | Q42: 0 | R42: 0 | S42: 0 | T42: 0 | U42: 0 | V42: 0
A43: Covenant add-backs | B43: $mm | C43: 0 | D43: 0 | E43: 0 | F43: 0 | G43: 0 | H43: 0 | I43: 0 | J43: 0 | K43: 0 | L43: 0 | M43: 0 | N43: 0 | O43: 0 | P43: 0 | Q43: 0 | R43: 0 | S43: 0 | T43: 0 | U43: 0 | V43: 0
A44: DSO | B44: days | C44: 67 | D44: 67 | E44: 67 | F44: 75 | G44: 75 | H44: 75 | I44: 75 | J44: 72 | K44: 72 | L44: 72 | M44: 72 | N44: 69 | O44: 69 | P44: 69 | Q44: 69 | R44: 67 | S44: 67 | T44: 67 | U44: 67 | V44: 66
A45: WIP / annualized revenue | B45: % | C45: 0.07 | D45: 0.07 | E45: 0.07 | F45: 0.08 | G45: 0.08 | H45: 0.08 | I45: 0.08 | J45: 0.075 | K45: 0.075 | L45: 0.075 | M45: 0.075 | N45: 0.07 | O45: 0.07 | P45: 0.07 | Q45: 0.07 | R45: 0.068 | S45: 0.068 | T45: 0.068 | U45: 0.068 | V45: 0.066
A46: Prepaids / annualized revenue | B46: % | C46: 0.012 | D46: 0.012 | E46: 0.012 | F46: 0.012 | G46: 0.012 | H46: 0.012 | I46: 0.012 | J46: 0.012 | K46: 0.012 | L46: 0.012 | M46: 0.012 | N46: 0.012 | O46: 0.012 | P46: 0.012 | Q46: 0.012 | R46: 0.012 | S46: 0.012 | T46: 0.012 | U46: 0.012 | V46: 0.012
A47: AP / annualized revenue | B47: % | C47: 0.055 | D47: 0.055 | E47: 0.055 | F47: 0.055 | G47: 0.055 | H47: 0.055 | I47: 0.055 | J47: 0.055 | K47: 0.055 | L47: 0.055 | M47: 0.055 | N47: 0.055 | O47: 0.055 | P47: 0.055 | Q47: 0.055 | R47: 0.055 | S47: 0.055 | T47: 0.055 | U47: 0.055 | V47: 0.055
A48: Accruals / annualized revenue | B48: % | C48: 0.075 | D48: 0.075 | E48: 0.075 | F48: 0.075 | G48: 0.075 | H48: 0.075 | I48: 0.075 | J48: 0.075 | K48: 0.075 | L48: 0.075 | M48: 0.075 | N48: 0.075 | O48: 0.075 | P48: 0.075 | Q48: 0.075 | R48: 0.075 | S48: 0.075 | T48: 0.075 | U48: 0.075 | V48: 0.075
A49: Deferred revenue / annualized revenue | B49: % | C49: 0.012 | D49: 0.012 | E49: 0.012 | F49: 0.012 | G49: 0.012 | H49: 0.012 | I49: 0.012 | J49: 0.012 | K49: 0.012 | L49: 0.012 | M49: 0.012 | N49: 0.012 | O49: 0.012 | P49: 0.012 | Q49: 0.012 | R49: 0.012 | S49: 0.012 | T49: 0.012 | U49: 0.012 | V49: 0.012
A50: Capex / revenue | B50: % | C50: 0.016 | D50: 0.016 | E50: 0.016 | F50: 0.016 | G50: 0.016 | H50: 0.016 | I50: 0.016 | J50: 0.016 | K50: 0.016 | L50: 0.016 | M50: 0.016 | N50: 0.016 | O50: 0.016 | P50: 0.016 | Q50: 0.016 | R50: 0.016 | S50: 0.016 | T50: 0.016 | U50: 0.016 | V50: 0.016
... A70: Seasonality | B70: % | C70: 0.25 | D70: 0.26 | E70: 0.26 | F70: 0.23 | G70: 0.25 | H70: 0.26 | I70: 0.26 | J70: 0.23 | K70: 0.25 | L70: 0.26 | M70: 0.26 | N70: 0.23 | O70: 0.25 | P70: 0.26 | Q70: 0.26 | R70: 0.23 | S70: 0.25 | T70: 0.26 | U70: 0.26 | V70: 0.23
A72: Standalone Upside
A73: Revenue | B73: $mm | C73: 20.0725 | D73: 20.8754 | E73: 20.8754 | F73: 20.036369 | G73: 21.778662 | H73: 22.649809 | I73: 22.649809 | J73: 21.739461 | K73: 23.629849 | L73: 24.575043 | M73: 24.575043 | N73: 23.587315 | O73: 25.638386 | P73: 26.663921 | Q73: 26.663921 | R73: 25.592237 | S73: 27.817649 | T73: 28.930355 | U73: 28.930355 | V73: 27.767577
A74: Gross margin | B74: % | C74: 0.365 | D74: 0.365 | E74: 0.365 | F74: 0.372 | G74: 0.372 | H74: 0.372 | I74: 0.372 | J74: 0.378 | K74: 0.378 | L74: 0.378 | M74: 0.378 | N74: 0.382 | O74: 0.382 | P74: 0.382 | Q74: 0.382 | R74: 0.384 | S74: 0.384 | T74: 0.384 | U74: 0.384 | V74: 0.385
A75: Firm EBITDA | B75: $mm | C75: 3.2116 | D75: 3.340064 | E75: 3.340064 | F75: 3.3661101 | G75: 3.6588153 | H75: 3.8051679 | I75: 3.8051679 | J75: 3.7826662 | K75: 4.1115937 | L75: 4.2760574 | M75: 4.2760574 | N75: 4.2457167 | O75: 4.6149095 | P75: 4.7995059 | Q75: 4.7995059 | R75: 4.6833793 | S75: 5.0906297 | T75: 5.2942549 | U75: 5.2942549 | V75: 5.1370017
A76: One-time charges | B76: $mm | C76: 0 | D76: 0 | E76: 0 | F76: 0 | G76: 0 | H76: 0 | I76: 0 | J76: 0 | K76: 0 | L76: 0 | M76: 0 | N76: 0 | O76: 0 | P76: 0 | Q76: 0 | R76: 0 | S76: 0 | T76: 0 | U76: 0 | V76: 0
A77: Covenant add-backs | B77: $mm | C77: 0 | D77: 0 | E77: 0 | F77: 0 | G77: 0 | H77: 0 | I77: 0 | J77: 0 | K77: 0 | L77: 0 | M77: 0 | N77: 0 | O77: 0 | P77: 0 | Q77: 0 | R77: 0 | S77: 0 | T77: 0 | U77: 0 | V77: 0
A78: DSO | B78: days | C78: 62 | D78: 62 | E78: 62 | F78: 60 | G78: 60 | H78: 60 | I78: 60 | J78: 59 | K78: 59 | L78: 59 | M78: 59 | N78: 58 | O78: 58 | P78: 58 | Q78: 58 | R78: 58 | S78: 58 | T78: 58 | U78: 58 | V78: 58
A79: WIP / annualized revenue | B79: % | C79: 0.065 | D79: 0.065 | E79: 0.065 | F79: 0.062 | G79: 0.062 | H79: 0.062 | I79: 0.062 | J79: 0.06 | K79: 0.06 | L79: 0.06 | M79: 0.06 | N79: 0.058 | O79: 0.058 | P79: 0.058 | Q79: 0.058 | R79: 0.057 | S79: 0.057 | T79: 0.057 | U79: 0.057 | V79: 0.056
A80: Prepaids / annualized revenue | B80: % | C80: 0.012 | D80: 0.012 | E80: 0.012 | F80: 0.012 | G80: 0.012 | H80: 0.012 | I80: 0.012 | J80: 0.012 | K80: 0.012 | L80: 0.012 | M80: 0.012 | N80: 0.012 | O80: 0.012 | P80: 0.012 | Q80: 0.012 | R80: 0.012 | S80: 0.012 | T80: 0.012 | U80: 0.012 | V80: 0.012
A81: AP / annualized revenue | B81: % | C81: 0.055 | D81: 0.055 | E81: 0.055 | F81: 0.055 | G81: 0.055 | H81: 0.055 | I81: 0.055 | J81: 0.055 | K81: 0.055 | L81: 0.055 | M81: 0.055 | N81: 0.055 | O81: 0.055 | P81: 0.055 | Q81: 0.055 | R81: 0.055 | S81: 0.055 | T81: 0.055 | U81: 0.055 | V81: 0.055
...

Sheet SB_Base
A1: Project Keystone - Standalone Base Quarterly LBO ($mm)
A3: Line Item | B3: Unit | C3: 46203 | D3: 46295 | E3: 46387 | F3: 46477 | G3: 46568 | H3: 46660 | I3: 46752 | J3: 46843 | K3: 46934 | L3: 47026 | M3: 47118 | N3: 47208 | O3: 47299 | P3: 47391 | Q3: 47483 | R3: 47573 | S3: 47664 | T3: 47756 | U3: 47848 | V3: 47938
A4: Operating Model
A5: Revenue | B5: $mm | C5: ='Scenario_Drivers'!C5 | D5: ='Scenario_Drivers'!D5 | E5: ='Scenario_Drivers'!E5 | F5: ='Scenario_Drivers'!F5 | G5: ='Scenario_Drivers'!G5 | H5: ='Scenario_Drivers'!H5 | I5: ='Scenario_Drivers'!I5 | J5: ='Scenario_Drivers'!J5 | ... V5: ='Scenario_Drivers'!V5
A6: Growth | B6: % | C6: =C5/(74.0*'Scenario_Drivers'!C36)-1 | D6: =D5/C5-1 | E6: =E5/D5-1 | F6: =F5/V5-1 | G6: =G5/F5-1 | H6: =H5/G5-1 | I6: =I5/H5-1 | J6: =J5/F5-1 | K6: =K5/J5-1 | L6: =L5/K5-1 | M6: =M5/L5-1 | N6: =N5/J5-1 | O6: =O5/N5-1 | P6: =P5/O5-1 | Q6: =Q5/P5-1 | R6: =R5/N5-1 | S6: =S5/R5-1 | T6: =T5/S5-1 | U6: =U5/T5-1 | V6: =V5/R5-1
A7: Gross margin | B7: % | C7: ='Scenario_Drivers'!C6 | D7: ='Scenario_Drivers'!D6 | E7: ='Scenario_Drivers'!E6 | F7: ='Scenario_Drivers'!F6 | G7: ='Scenario_Drivers'!G6 | H7: ='Scenario_Drivers'!H6 | I7: ='Scenario_Drivers'!I6 | J7: ='Scenario_Drivers'!J6 | ... V7: ='Scenario_Drivers'!V6
A8: Gross profit | B8: $mm | C8: =C5*C7 | D8: =D5*D7 | E8: =E5*E7 | F8: =F5*F7 | G8: =G5*G7 | H8: =H5*H7 | I8: =I5*I7 | J8: =J5*J7 | ... V8: =V5*V7
A9: COGS | B9: $mm | C9: =-(C5-C8) | D9: =-(D5-D8) | E9: =-(E5-E8) | F9: =-(F5-F8) | G9: =-(G5-G8) | H9: =-(H5-H8) | I9: =-(I5-I8) | J9: =-(J5-J8) | ... V9: =-(V5-V8)
A10: Firm EBITDA | B10: $mm | C10: ='Scenario_Drivers'!C7 | D10: ='Scenario_Drivers'!D7 | E10: ='Scenario_Drivers'!E7 | F10: ='Scenario_Drivers'!F7 | G10: ='Scenario_Drivers'!G7 | H10: ='Scenario_Drivers'!H7 | I10: ='Scenario_Drivers'!I7 | J10: ='Scenario_Drivers'!J7 | ... V10: ='Scenario_Drivers'!V7
A11: One-time charges | B11: $mm | C11: =-'Scenario_Drivers'!C8 | D11: =-'Scenario_Drivers'!D8 | E11: =-'Scenario_Drivers'!E8 | F11: =-'Scenario_Drivers'!F8 | G11: =-'Scenario_Drivers'!G8 | H11: =-'Scenario_Drivers'!H8 | I11: =-'Scenario_Drivers'!I8 | J11: =-'Scenario_Drivers'!J8 | ... V11: =-'Scenario_Drivers'!V8
A12: Reported EBITDA | B12: $mm | C12: =C10+C11 | D12: =D10+D11 | E12: =E10+E11 | F12: =F10+F11 | G12: =G10+G11 | H12: =H10+H11 | I12: =I10+I11 | J12: =J10+J11 | ... V12: =V10+V11
A13: Covenant add-backs | B13: $mm | C13: ='Scenario_Drivers'!C9 | D13: ='Scenario_Drivers'!D9 | E13: ='Scenario_Drivers'!E9 | F13: ='Scenario_Drivers'!F9 | G13: ='Scenario_Drivers'!G9 | H13: ='Scenario_Drivers'!H9 | I13: ='Scenario_Drivers'!I9 | J13: ='Scenario_Drivers'!J9 | ... V13: ='Scenario_Drivers'!V9
A14: Covenant EBITDA | B14: $mm | C14: =C12+C13 | D14: =D12+D13 | E14: =E12+E13 | F14: =F12+F13 | G14: =G12+G13 | H14: =H12+H13 | I14: =I12+I13 | J14: =J12+J13 | ... V14: =V12+V13
A15: Firm EBITDA margin | B15: % | C15: =C10/C5 | D15: =D10/D5 | E15: =E10/E5 | F15: =F10/F5 | G15: =G10/G5 | H15: =H10/H5 | I15: =I10/I5 | J15: =J10/J5 | ... V15: =V10/V5
A16: Income Statement
A17: Depreciation | B17: $mm | C17: =C5*Inputs!$B$17 | D17: =D5*Inputs!$B$17 | E17: =E5*Inputs!$B$17 | F17: =F5*Inputs!$B$17 | G17: =G5*Inputs!$B$17 | H17: =H5*Inputs!$B$17 | I17: =I5*Inputs!$B$17 | J17: =J5*Inputs!$B$17 | ... V17: =V5*Inputs!$B$17
A18: Core PPA amortization | B18: $mm | C18: ='Scenario_Drivers'!C35 | D18: ='Scenario_Drivers'!D35 | E18: ='Scenario_Drivers'!E35 | F18: ='Scenario_Drivers'!F35 | G18: ='Scenario_Drivers'!G35 | H18: ='Scenario_Drivers'!H35 | I18: ='Scenario_Drivers'!I35 | J18: ='Scenario_Drivers'!J35 | ... V18: ='Scenario_Drivers'!V35
A19: Integration asset amortization | B19: $mm | C19: =0 | D19: =0 | E19: =0 | F19: =0 | G19: =0 | H19: =0 | I19: =0 | J19: =0 | ... V19: =0
A20: Total D&A | B20: $mm | C20: =SUM(C17:C19) | D20: =SUM(D17:D19) | E20: =SUM(E17:E19) | F20: =SUM(F17:F19) | G20: =SUM(G17:G19) | H20: =SUM(H17:H19) | I20: =SUM(I17:I19) | J20: =SUM(J17:J19) | ... V20: =SUM(V17:V19)
A21: EBIT | B21: $mm | C21: =C12-C20 | D21: =D12-D20 | E21: =E12-E20 | F21: =F12-F20 | G21: =G12-G20 | H21: =H12-H20 | I21: =I12-I20 | J21: =J12-J20 | ... V21: =V12-V20
A22: Cash interest | B22: $mm | C22: =-((('S&U_Opening'!$E$18+MAX(0,'S&U_Opening'!$E$18-(MIN(0.107,'S&U_Opening'!$E$18))))/2)*(MAX('Scenario_Drivers'!C33,Inputs!$B$26)+Inputs!$B$23+'Scenario_Drivers'!C34)/4+((0+0+'Scenario_Drivers'!C25-(IF(0>0,MIN(0.015,0),0)))/2)*(MAX('Scenario_Drivers'!C33,Inputs!$B$26)+Inputs!$B$25+'Scenario_Drivers'!C34)/4+0*(MAX('Scenario_Drivers'!C33,Inputs!$B$26)+Inputs!$B$24+'Scenario_Drivers'!C34)/4+MAX(0,Inputs!$B$20-0-'Scenario_Drivers'!C28)*Inputs!$B$29/4+0) | D22: =-(((C76+MAX(0,C76-(MIN(0.107,C76))))/2)*(MAX('Scenario_Drivers'!D33,Inputs!$B$26)+Inputs!$B$23+'Scenario_Drivers'!D34)/4+((C77+C77+'Scenario_Drivers'!D25-(IF(C77>0,MIN(0.015,C77),0)))/2)*(MAX('Scenario_Drivers'!D33,Inputs!$B$26)+Inputs!$B$25+'Scenario_Drivers'!D34)/4+C78*(MAX('Scenario_Drivers'!D33,Inputs!$B$26)+Inputs!$B$24+'Scenario_Drivers'!D34)/4+MAX(0,Inputs!$B$20-C78-'Scenario_Drivers'!D28)*Inputs!$B$29/4+MAX(0,Inputs!$B$21-C77-'Scenario_Drivers'!D25)*Inputs!$B$30/4) | E22: =-(((D76+MAX(0,D76-(MIN(0.107,D76))))/2)*(MAX('Scenario_Drivers'!E33,Inputs!$B$26)+Inputs!$B$23+'Scenario_Drivers'!E34)/4+((D77+D77+'Scenario_Drivers'!E25-(IF(D77>0,MIN(0.015,D77),0)))/2)*(MAX('Scenario_Drivers'!E33,Inputs!$B$26)+Inputs!$B$25+'Scenario_Drivers'!E34)/4+D78*(MAX('Scenario_Drivers'!E33,Inputs!$B$26)+Inputs!$B$24+'Scenario_Drivers'!E34)/4+MAX(0,Inputs!$B$20-D78-'Scenario_Drivers'!E28)*Inputs!$B$29/4+MAX(0,Inputs!$B$21-D77-'Scenario_Drivers'!E25)*Inputs!$B$30/4) | F22: =-(((E76+MAX(0,E76-(MIN(0.107,E76))))/2)*(MAX('Scenario_Drivers'!F33,Inputs!$B$26)+Inputs!$B$23+'Scenario_Drivers'!F34)/4+((E77+E77+'Scenario_Drivers'!F25-(IF(E77>0,MIN(0.015,E77),0)))/2)*(MAX('Scenario_Drivers'!F33,Inputs!$B$26)+Inputs!$B$25+'Scenario_Drivers'!F34)/4+E78*(MAX('Scenario_Drivers'!F33,Inputs!$B$26)+Inputs!$B$24+'Scenario_Drivers'!F34)/4+MAX(0,Inputs!$B$20-E78-'Scenario_Drivers'!F28)*Inputs!$B$29/4+MAX(0,Inputs!$B$21-E77-'Scenario_Drivers'!F25)*Inputs!$B$30/4) | G22: =-(((F76+MAX(0,F76-(MIN(0.107,F76))))/2)*(MAX('Scenario_Drivers'!G33,Inputs!$B$26)+Inputs!$B$23+'Scenario_Drivers'!G34)/4+((F77+F77+'Scenario_Drivers'!G25-(IF(F77>0,MIN(0.015,F77),0)))/2)*(MAX('Scenario_Drivers'!G33,Inputs!$B$26)+Inputs!$B$25+'Scenario_Drivers'!G34)/4+F78*(MAX('Scenario_Drivers'!G33,Inputs!$B$26)+Inputs!$B$24+'Scenario_Drivers'!G34)/4+MAX(0,Inputs!$B$20-F78-'Scenario_Drivers'!G28)*Inputs!$B$29/4+MAX(0,Inputs!$B$21-F77-'Scenario_Drivers'!G25)*Inputs!$B$30/4) | H22: =-(((G76+MAX(0,G76-(MIN(0.107,G76))))/2)*(MAX('Scenario_Drivers'!H33,Inputs!$B$26)+Inputs!$B$23+'Scenario_Drivers'!H34)/4+((G77+G77+'Scenario_Drivers'!H25-(IF(G77>0,MIN(0.015,G77),0)))/2)*(MAX('Scenario_Drivers'!H33,Inputs!$B$26)+Inputs!$B$25+'Scenario_Drivers'!H34)/4+G78*(MAX('Scenario_Drivers'!H33,Inputs!$B$26)+Inputs!$B$24+'Scenario_Drivers'!H34)/4+MAX(0,Inputs!$B$20-G78-'Scenario_Drivers'!H28)*Inputs!$B$29/4+MAX(0,Inputs!$B$21-G77-'Scenario_Drivers'!H25)*Inputs!$B$30/4) | I22: =-(((H76+MAX(0,H76-(MIN(0.107,H76))))/2)*(MAX('Scenario_Drivers'!I33,Inputs!$B$26)+Inputs!$B$23+'Scenario_Drivers'!I34)/4+((H77+H77+'Scenario_Drivers'!I25-(IF(H77>0,MIN(0.015,H77),0)))/2)*(MAX('Scenario_Drivers'!I33,Inputs!$B$26)+Inputs!$B$25+'Scenario_Drivers'!I34)/4+H78*(MAX('Scenario_Drivers'!I33,Inputs!$B$26)+Inputs!$B$24+'Scenario_Drivers'!I34)/4+MAX(0,Inputs!$B$20-H78-'Scenario_Drivers'!I28)*Inputs!$B$29/4+0) | J22: =-(((I76+MAX(0,I76-(MIN(0.107,I76))))/2)*(MAX('Scenario_Drivers'!J33,Inputs!$B$26)+Inputs!$B$23+'Scenario_Drivers'!J34)/4+((I77+I77+'Scenario_Drivers'!J25-(IF(I77>0,MIN(0.015,I77),0)))/2)*(MAX('Scenario_Drivers'!J33,Inputs!$B$26)+Inputs!$B$25+'Scenario_Drivers'!J34)/4+I78*(MAX('Scenario_Drivers'!J33,Inputs!$B$26)+Inputs!$B$24+'Scenario_Drivers'!J34)/4+MAX(0,Inputs!$B$20-I78-'Scenario_Drivers'!J28)*Inputs!$B$29/4+0) | K22: =-(((J76+MAX(0,J76-(MIN(0.107,J76))))/2)*(MAX('Scenario_Drivers'!K33,Inputs!$B$26)+Inputs!$B$23+'Scenario_Drivers'!K34)/4+((J77+J77+'Scenario_Drivers'!K25-(IF(J77>0,MIN(0.015,J77),0)))/2)*(MAX('Scenario_Drivers'!K33,Inputs!$B$26)+Inputs!$B$25+'Scenario_Drivers'!K34)/4+J78*(MAX('Scenario_Drivers'!K33,Inputs!$B$26)+Inputs!$B$24+'Scenario_Drivers'!K34)/4+MAX(0,Inputs!$B$20-J78-'Scenario_Drivers'!K28)*Inputs!$B$29/4+0) | L22: =-(((K76+MAX(0,K76-(MIN(0.107,K76))))/2)*(MAX('Scenario_Drivers'!L33,Inputs!$B$26)+Inputs!$B$23+'Scenario_Drivers'!L34)/4+((K77+K77+'Scenario_Drivers'!L25-(IF(K77>0,MIN(0.015,K77),0)))/2)*(MAX('Scenario_Drivers'!L33,Inputs!$B$26)+Inputs!$B$25+'Scenario_Drivers'!L34)/4+K78*(MAX('Scenario_Drivers'!L33,Inputs!$B$26)+Inputs!$B$24+'Scenario_Drivers'!L34)/4+MAX(0,Inputs!$B$20-K78-'Scenario_Drivers'!L28)*Inputs!$B$29/4+0) | M22: =-(((L76+MAX(0,L76-(MIN(0.107,L76))))/2)*(MAX('Scenario_Drivers'!M33,Inputs!$B$26)+Inputs!$B$23+'Scenario_Drivers'!M34)/4+((L77+L77+'Scenario_Drivers'!M25-(IF(L77>0,MIN(0.015,L77),0)))/2)*(MAX('Scenario_Drivers'!M33,Inputs!$B$26)+Inputs!$B$25+'Scenario_Drivers'!M34)/4+L78*(MAX('Scenario_Drivers'!M33,Inputs!$B$26)+Inputs!$B$24+'Scenario_Drivers'!M34)/4+MAX(0,Inputs!$B$20-L78-'Scenario_Drivers'!M28)*Inputs!$B$29/4+0) | N22: =-(((M76+MAX(0,M76-(MIN(0.107,M76))))/2)*(MAX('Scenario_Drivers'!N33,Inputs!$B$26)+Inputs!$B$23+'Scenario_Drivers'!N34)/4+((M77+M77+'Scenario_Drivers'!N25-(IF(M77>0,MIN(0.015,M77),0)))/2)*(MAX('Scenario_Drivers'!N33,Inputs!$B$26)+Inputs!$B$25+'Scenario_Drivers'!N34)/4+M78*(MAX('Scenario_Drivers'!N33,Inputs!$B$26)+Inputs!$B$24+'Scenario_Drivers'!N34)/4+MAX(0,Inputs!$B$20-M78-'Scenario_Drivers'!N28)*Inputs!$B$29/4+0) | O22: =-(((N76+MAX(0,N76-(MIN(0.107,N76))))/2)*(MAX('Scenario_Drivers'!O33,Inputs!$B$26)+Inputs!$B$23+'Scenario_Drivers'!O34)/4+((N77+N77+'Scenario_Drivers'!O25-(IF(N77>0,MIN(0.015,N77),0)))/2)*(MAX('Scenario_Drivers'!O33,Inputs!$B$26)+Inputs!$B$25+'Scenario_Drivers'!O34)/4+N78*(MAX('Scenario_Drivers'!O33,Inputs!$B$26)+Inputs!$B$24+'Scenario_Drivers'!O34)/4+MAX(0,Inputs!$B$20-N78-'Scenario_Drivers'!O28)*Inputs!$B$29/4+0) | P22: =-(((O76+MAX(0,O76-(MIN(0.107,O76))))/2)*(MAX('Scenario_Drivers'!P33,Inputs!$B$26)+Inputs!$B$23+'Scenario_Drivers'!P34)/4+((O77+O77+'Scenario_Drivers'!P25-(IF(O77>0,MIN(0.015,O77),0)))/2)*(MAX('Scenario_Drivers'!P33,Inputs!$B$26)+Inputs!$B$25+'Scenario_Drivers'!P34)/4+O78*(MAX('Scenario_Drivers'!P33,Inputs!$B$26)+Inputs!$B$24+'Scenario_Drivers'!P34)/4+MAX(0,Inputs!$B$20-O78-'Scenario_Drivers'!P28)*Inputs!$B$29/4+0) | ... V22: =-(((U76+MAX(0,U76-(MIN(0.107,U76))))/2)*(MAX('Scenario_Drivers'!V33,Inputs!$B$26)+Inputs!$B$23+'Scenario_Drivers'!V34)/4+((U77+U77+'Scenario_Drivers'!V25-(IF(U77>0,MIN(0.015,U77),0)))/2)*(MAX('Scenario_Drivers'!V33,Inputs!$B$26)+Inputs!$B$25+'Scenario_Drivers'!V34)/4+U78*(MAX('Scenario_Drivers'!V33,Inputs!$B$26)+Inputs!$B$24+'Scenario_Drivers'!V34)/4+MAX(0,Inputs!$B$20-U78-'Scenario_Drivers'!V28)*Inputs!$B$29/4+0)
A23: Financing fee amortization | B23: $mm | C23: =MIN('S&U_Opening'!$B$24,1.4/24) | D23: =MIN(C73,1.4/24) | E23: =MIN(D73,1.4/24) | F23: =MIN(E73,1.4/24) | G23: =MIN(F73,1.4/24) | H23: =MIN(G73,1.4/24) | I23: =MIN(H73,1.4/24) | J23: =MIN(I73,1.4/24) | K23: =MIN(J73,1.4/24) | ... V23: =MIN(U73,1.4/24)
A24: Interest income | B24: $mm | C24: ='S&U_Opening'!$B$15*1.0%/4 | D24: =C67*1.0%/4 | E24: =D67*1.0%/4 | F24: =E67*1.0%/4 | G24: =F67*1.0%/4 | H24: =G67*1.0%/4 | I24: =H67*1.0%/4 | J24: =I67*1.0%/4 | K24: =J67*1.0%/4 | ... V24: =U67*1.0%/4
A25: Pre-tax income | B25: $mm | C25: =C21+C22-C23+C24 | D25: =D21+D22-D23+D24 | E25: =E21+E22-E23+E24 | F25: =F21+F22-F23+F24 | G25: =G21+G22-G23+G24 | H25: =H21+H22-H23+H24 | I25: =I21+I22-I23+I24 | J25: =J21+J22-J23+J24 | ... V25: =V21+V22-V23+V24
A26: Book tax expense | B26: $mm | C26: =-MAX(0,C25*Inputs!$B$15) | D26: =-MAX(0,D25*Inputs!$B$15) | E26: =-MAX(0,E25*Inputs!$B$15) | F26: =-MAX(0,F25*Inputs!$B$15) | G26: =-MAX(0,G25*Inputs!$B$15) | H26: =-MAX(0,H25*Inputs!$B$15) | I26: =-MAX(0,I25*Inputs!$B$15) | J26: =-MAX(0,J25*Inputs!$B$15) | ... V26: =-MAX(0,V25*Inputs!$B$15)
A27: Cash taxes | B27: $mm | C27: =-MAX(0,(C116-0)*Inputs!$B$15) | D27: =-MAX(0,(D116-C115)*Inputs!$B$15) | E27: =-MAX(0,(E116-D115)*Inputs!$B$15) | F27: =-MAX(0,(F116-E115)*Inputs!$B$15) | G27: =-MAX(0,(G116-F115)*Inputs!$B$15) | H27: =-MAX(0,(H116-G115)*Inputs!$B$15) | I27: =-MAX(0,(I116-H115)*Inputs!$B$15) | J27: =-MAX(0,(J116-I115)*Inputs!$B$15) | K27: =-MAX(0,(K116-J115)*Inputs!$B$15) | ... V27: =-MAX(0,(V116-U115)*Inputs!$B$15)
A28: Net income | B28: $mm | C28: =C25+C26 | D28: =D25+D26 | E28: =E25+E26 | F28: =F25+F26 | G28: =G25+G26 | H28: =H25+H26 | I28: =I25+I26 | J28: =J25+J26 | ... V28: =V25+V26
A29: Working Capital and Capital Expenditure
A30: Accounts receivable | B30: $mm | C30: =(C5/'Scenario_Drivers'!C36)*'Scenario_Drivers'!C10/365 | D30: =(D5/'Scenario_Drivers'!D36)*'Scenario_Drivers'!D10/365 | E30: =(E5/'Scenario_Drivers'!E36)*'Scenario_Drivers'!E10/365 | F30: =(F5/'Scenario_Drivers'!F36)*'Scenario_Drivers'!F10/365 | G30: =(G5/'Scenario_Drivers'!G36)*'Scenario_Drivers'!G10/365 | H30: =(H5/'Scenario_Drivers'!H36)*'Scenario_Drivers'!H10/365 | I30: =(I5/'Scenario_Drivers'!I36)*'Scenario_Drivers'!I10/365 | J30: =(J5/'Scenario_Drivers'!J36)*'Scenario_Drivers'!J10/365 | ... V30: =(V5/'Scenario_Drivers'!V36)*'Scenario_Drivers'!V10/365
A31: Unbilled WIP | B31: $mm | C31: =(C5/'Scenario_Drivers'!C36)*'Scenario_Drivers'!C11 | D31: =(D5/'Scenario_Drivers'!D36)*'Scenario_Drivers'!D11 | E31: =(E5/'Scenario_Drivers'!E36)*'Scenario_Drivers'!E11 | F31: =(F5/'Scenario_Drivers'!F36)*'Scenario_Drivers'!F11 | G31: =(G5/'Scenario_Drivers'!G36)*'Scenario_Drivers'!G11 | H31: =(H5/'Scenario_Drivers'!H36)*'Scenario_Drivers'!H11 | I31: =(I5/'Scenario_Drivers'!I36)*'Scenario_Drivers'!I11 | J31: =(J5/'Scenario_Drivers'!J36)*'Scenario_Drivers'!J11 | ... V31: =(V5/'Scenario_Drivers'!V36)*'Scenario_Drivers'!V11
A32: Prepaids | B32: $mm | C32: =(C5/'Scenario_Drivers'!C36)*'Scenario_Drivers'!C12 | D32: =(D5/'Scenario_Drivers'!D36)*'Scenario_Drivers'!D12 | E32: =(E5/'Scenario_Drivers'!E36)*'Scenario_Drivers'!E12 | F32: =(F5/'Scenario_Drivers'!F36)*'Scenario_Drivers'!F12 | G32: =(G5/'Scenario_Drivers'!G36)*'Scenario_Drivers'!G12 | H32: =(H5/'Scenario_Drivers'!H36)*'Scenario_Drivers'!H12 | I32: =(I5/'Scenario_Drivers'!I36)*'Scenario_Drivers'!I12 | J32: =(J5/'Scenario_Drivers'!J36)*'Scenario_Drivers'!J12 | ... V32: =(V5/'Scenario_Drivers'!V36)*'Scenario_Drivers'!V12
A33: Accounts payable | B33: $mm | C33: =(C5/'Scenario_Drivers'!C36)*'Scenario_Drivers'!C13 | D33: =(D5/'Scenario_Drivers'!D36)*'Scenario_Drivers'!D13 | E33: =(E5/'Scenario_Drivers'!E36)*'Scenario_Drivers'!E13 | F33: =(F5/'Scenario_Drivers'!F36)*'Scenario_Drivers'!F13 | G33: =(G5/'Scenario_Drivers'!G36)*'Scenario_Drivers'!G13 | H33: =(H5/'Scenario_Drivers'!H36)*'Scenario_Drivers'!H13 | I33: =(I5/'Scenario_Drivers'!I36)*'Scenario_Drivers'!I13 | J33: =(J5/'Scenario_Drivers'!J36)*'Scenario_Drivers'!J13 | ... V33: =(V5/'Scenario_Drivers'!V36)*'Scenario_Drivers'!V13
